<?xml version="1.0" ?>
 
<robot name="mrm" xmlns:xacro="http://www.ros.org/wiki/xacro">
    <link name="base_link">
        <visual>
            <origin rpy="0 0 0" xyz="0 0 0.075"/>
            <geometry>
                <cylinder radius="0.8" length="0.15"/>
            </geometry>
        </visual>
    </link>
    
    <joint name="base_link_link_1" type="revolute">
        <axis xyz="0 0 1" />
        <limit effort="1000.0" lower="-3.14" upper="3.14" velocity="0.5" />
        <origin rpy="0 0 0" xyz="0 0 0.15"/>
        <parent link="base_link"/>
        <child link="link1"/>
    </joint>
    
    <link name="link1">
        <visual>
            <origin rpy="0 0 0" xyz="0 0 0.2"/>
            <geometry>
                <cylinder radius="0.35" length="0.4"/>
            </geometry>
        </visual>
    </link>

    <joint name="my_first_link1_link_2" type="revolute">
        <axis xyz="0 1 0" />
        <limit effort="1000.0" lower="-0.5" upper="0.5" velocity="0.5" />
        <origin rpy="0 0 0" xyz="0 0 0.4"/>
        <parent link="link1"/>
        <child link="link2"/>
    </joint>

    <link name="link2">
        <visual>
            <origin rpy="0 0 0" xyz="0 0 0.4"/>
            <geometry>
                <box size="0.2 0.4 0.8"/>
            </geometry>
        </visual>
    </link>

    <joint name="link2_link_3" type="revolute">
        <axis xyz="0 1 0" />
        <limit effort="1000.0" lower="0" upper="1" velocity="0.5" />
        <origin rpy="0 0 0" xyz="0 0 0.8"/>
        <parent link="link2"/>
        <child link="link3"/>
    </joint>

    <link name="link3">
        <visual>
            <origin rpy="0 0 0" xyz="0 0 0.4"/>
            <geometry>
                <cylinder radius="0.10" length="0.8"/>
            </geometry>
        </visual>
    </link>

    <joint name="link3_link_4" type="revolute">
        <axis xyz="0 1 0" />
        <limit effort="1000.0" lower="0" upper="1" velocity="0.5" />
        <origin rpy="0 0 0" xyz="0 0 0.8"/>
        <parent link="link3"/>
        <child link="link4"/>
    </joint>

    <link name="link4">
        <visual>
            <origin rpy="0 0 0" xyz="0 0 0.4"/>
            <geometry>
                <cylinder radius="0.05" length="0.8"/>
            </geometry>
        </visual>
    </link>


    <joint name="link4_link_5" type="fixed">
        <axis xyz="0 1 0" />
        <limit effort="1000.0" lower="0" upper="1" velocity="0.5" />
        <origin rpy="0 0 0" xyz="0 0 0.8"/>
        <parent link="link4"/>
        <child link="link5"/>
    </joint>

    <link name="link5">
        <visual>
            <origin rpy="0 0 0" xyz="0 0 0.05"/>
            <geometry>
                <box size="0.1 0.1 0.1"/>
            </geometry>
        </visual>
    </link>

    

</robot>
